Workbook

Sheet FUND 2025
A1: Names: | C1: 42005 | D1: 11324 | E1: 42036 | F1: 46784 | G1: 42064 | H1: 11383 | I1: 42095 | J1: 11049 | K1: 42125 | L1: 11444 | M1: 42156 | N1: 11110 | O1: 42186 | P1: 45868 | Q1: 45884 | R1: 45899 | S1: Penalty | W1: Tshirt | X1: Completed
A2: Ancaja, Louise | C2: 20 | D2: 20 | E2: 20 | F2: 20 | G2: 20 | H2: 10 | I2: 20 | J2: 20 | K2: 20 | L2: 20 | M2: 20 | N2: 20 | O2: 20 | W2: 315 | X2: /
A3: Azores, Leslie | C3: 20 | D3: 20 | E3: 20 | F3: 20 | G3: 20 | H3: 20 | S3: 34 | W3: 315 | X3: /
A4: Balanial, Pamela | C4: 20 | D4: 20 | E4: 20 | F4: 20 | G4: 20 | H4: 20 | I4: 20 | J4: 20 | K4: 20 | W4: 315 | X4: /
A5: Bamba, Jhon | C5: 20 | D5: 20 | W5: 315 | X5: /
A6: Barco, Isabel | C6: 20 | D6: 20 | E6: 20 | F6: 20 | G6: 20 | H6: 20 | I6: 20 | J6: 20 | K6: 20 | L6: 20 | M6: 20 | N6: 20 | O6: 20 | W6: 315 | X6: /
A7: Baria, Christine | C7: 20 | D7: 20 | E7: 20 | F7: 20 | G7: 20 | H7: 20 | I7: 20 | J7: 20 | K7: 20 | L7: 20 | M7: 20 | W7: 315 | X7: /
A8: Batad, Micha | C8: 20 | D8: 20 | E8: 20 | F8: 20 | G8: 20 | H8: 20 | I8: 20 | J8: 20 | K8: 20 | L8: 20 | M8: 20 | N8: 20 | O8: 20 | W8: 315 | X8: /
A9: Biler, Kehn | C9: NEW | D9: 20 | E9: 20 | F9: 20 | G9: 20 | H9: 20 | I9: 20 | J9: 20 | K9: 20 | L9: 20 | M9: 20 | N9: 20 | O9: 20 | W9: 315 | X9: -
A10: Capistrano, Robiel | C10: 20 | D10: 20 | E10: 20 | F10: 20 | G10: 20 | H10: 20 | I10: 20 | J10: 20 | K10: 20 | L10: 20 | M10: 20 | N10: 20 | O10: 20 | P10: 20 | Q10: 20 | W10: 315 | X10: /
A11: De dios, Rea | C11: 20 | D11: 20 | E11: 20 | F11: 20 | G11: 20 | H11: 20 | I11: 20 | J11: 20 | K11: 20 | L11: 20 | M11: 20 | N11: 20 | O11: 20 | W11: 315 | X11: /
A12: Domanais, Karl | C12: 20 | D12: 20 | E12: 20 | F12: 20 | G12: 20 | H12: 20 | I12: 20 | J12: 20 | K12: 20 | L12: 20 | M12: 20 | N12: 20 | O12: 20 | P12: 20 | Q12: 20 | R12: 10 | W12: 315 | X12: /
A13: Frias, Maryl | C13: 20 | D13: 20 | E13: 20 | F13: 20 | G13: 20 | H13: 20 | I13: 20 | J13: 20 | K13: 20 | L13: 20 | M13: 20 | N13: 20 | O13: 20 | W13: 315 | X13: /
A14: Gaddi, Rex Jr. | C14: 20 | D14: 20 | E14: 20 | F14: 20 | G14: 20 | H14: 20 | I14: 20 | J14: 20 | K14: 20 | L14: 20 | M14: 20 | N14: 20 | O14: 20 | S14: 34 | W14: 315 | X14: /
A15: Guzman, Xyril | C15: 20 | D15: 20 | E15: 20 | F15: 20 | G15: 20 | H15: 20 | I15: 20 | J15: 20 | K15: 20 | L15: 20 | M15: 20 | N15: 20 | O15: 20 | W15: 315 | X15: /
A16: La Lisan, Quert | W16: 315 | X16: 1
A17: Labitigan, Reynalyn | C17: NEW | D17: 20 | E17: 20 | F17: 20 | G17: 20 | H17: 20 | I17: 20 | J17: 20 | W17: 315 | X17: -
A18: Lista, Jamaica | C18: 20 | D18: 20 | W18: 315 | X18: /
A19: Macaraig, Jay Cee | C19: 20 | D19: 20 | E19: 20 | F19: 20 | G19: 20 | H19: 20 | I19: 20 | J19: 20 | K19: 20 | L19: 20 | M19: 20 | N19: 20 | W19: 315 | X19: /
A20: Malonzo, Nizza | C20: 20 | D20: 20 | E20: 20 | F20: 20 | G20: 20 | H20: 20 | I20: 20 | J20: 20 | K20: 20 | W20: 315 | X20: /
A21: Mendoza, Louis | C21: 20 | D21: 20 | E21: 20 | F21: 20 | G21: 20 | H21: 20 | I21: 20 | J21: 20 | K21: 20 | L21: 20 | M21: 20 | N21: 20 | W21: 315 | X21: /
A22: Ombao, Marlon Jr. | C22: NEW | D22: 20 | E22: 20 | F22: 20 | G22: 20 | H22: 20 | I22: 20 | J22: 20 | W22: 315 | X22: -
A23: Orozco, Maya | C23: 20 | D23: 20 | E23: 20 | F23: 20 | G23: 20 | H23: 20 | I23: 20 | S23: 35 | W23: 315
A24: Perillo, Amariel | C24: 20 | D24: 20 | E24: 20 | F24: 20 | G24: 20 | H24: 20 | I24: 20 | J24: 20 | K24: 20 | L24: 20 | M24: 20 | W24: 315 | X24: /
A25: Pilapil, Ericka | C25: 20 | D25: 20 | E25: 20 | F25: 20 | G25: 20 | H25: 20 | I25: 20 | J25: 20 | K25: 20 | L25: 20 | M25: 20 | W25: 315 | X25: /
A26: Quijano, Jerwin | C26: NEW | D26: 20 | E26: 20 | F26: 20 | G26: 20 | H26: 20 | W26: 315 | X26: -
A27: Quindoza, Aljo | C27: 20 | D27: 20 | E27: 20 | F27: 20 | G27: 20 | H27: 20 | I27: 20 | J27: 20 | W27: 315 | X27: /
A28: Rivera, Kate | C28: NEW | D28: NEW | E28: 20 | F28: 20 | G28: 20 | H28: 20 | I28: 20 | J28: 20 | K28: 20 | L28: 20 | M28: 20 | N28: 20 | O28: 20 | W28: 315 | X28: -
A29: Sesgundo, Kim | C29: 20 | D29: 20 | E29: 20 | F29: 20 | G29: 20 | H29: 20 | I29: 20 | J29: 20 | K29: 20 | L29: 20 | W29: 315 | X29: /
A30: Tomenio, Alyssa | C30: 20 | D30: 20 | E30: 20 | F30: 20 | G30: 20 | H30: 20 | W30: 315 | X30: /
A31: Valencia, Alexia | C31: 20 | D31: 20 | E31: 20 | F31: 20 | G31: 20 | H31: 20 | I31: 20 | J31: 20 | K31: 20 | L31: 20 | W31: 315 | X31: /
A32: Vinas, Jiro | C32: 20 | D32: 20 | E32: 20 | F32: 20 | G32: 20 | H32: 20 | I32: 20 | J32: 20 | K32: 20 | L32: 20 | W32: 315 | X32: /
A33: Dator,Jeffre | C33: NEW | D33: NEW | E33: 20 | F33: 20 | G33: 20 | H33: 20 | I33: 20 | J33: 20 | K33: 20 | L33: 20 | M33: 20 | N33: 20 | O33: 20 | P33: 20 | Q33: 20
A34: Gianan, Jean Nicole | C34: NEW | D34: NEW | E34: NEW | F34: NEW | G34: 20 | H34: 20 | I34: 20 | J34: 20 | K34: 20 | L34: 20 | M34: 20 | N34: 20 | O34: 20
W35: =SUM(W2:W8,W10:W16,W18:W21,W17,W23:W25,W27,W29:W32) -> 8505
B36: TOTAL | C36: =SUM(C2:C33) -> 500 | D36: =SUM(D2:D29) -> 520 | E36: =SUM(E2:E33) -> 580 | F36: =SUM(F2:F33) -> 580 | G36: =SUM(G2:G33) -> 580 | H36: =SUM(H2:H33) -> 570 | I36: =SUM(I2:I33) -> 520 | J36: =SUM(J2:J33) -> 500 | K36: =SUM(K2:K34) -> 460 | L36: =SUM(L2:L34) -> 420 | M36: =SUM(M2:M34) -> 360 | N36: =SUM(N2:N34) -> 300 | O36: =SUM(O2:O34) -> 260 | P36: =SUM(P2:P34) -> 60 | Q36: =SUM(Q2:Q34) -> 60 | R36: =SUM(R2:R34) -> 10
B38: Tomenio | C38: 60
B39: quert | C39: 40
B40: bamba | C40: 60
B41: Perillo | C41: 60
...

Sheet 2025 
A4: Fund Collection (1/15/25) | B4: ='FUND 2025'!C50 -> 1000
A5: Fund Collection (1/31/25) | B5: ='FUND 2025'!D36 -> 520
A6: Total | B6: =SUM(B4:B5) -> 1520 | F6: FUND (2024) | H6: 21210
B7: ='FUND 2025'!C54-B6 -> 985
A8: Total | B8: =SUM(B6:B7) -> 2505 | F8: Org Shirt (downpayment) | G8: 7000
A9: Fund Collection (2/15/25) | B9: ='FUND 2025'!E36 -> 580 | F9: Payment (gcash) | G9: 6920 | H9: =G8+G9 -> 13920
A10: TOTAL | B10: =SUM(B8:B9) -> 3085 | F10: Total | H10: =H6-G9 -> 14290
A11: Bamboo Stick | B11: -50 | J11: Total Org Shirt | K11: =32*435 -> 13920
A12: Mangrove, Transpo | B12: -300 | J12: Shirt Collection | K12: =31*315 -> 9765
A13: Fund Collection, (2/28/25) | B13: ='FUND 2025'!F36 -> 580 | J13: Adviser's Shirt | K13: 435
A14: TOTAL | B14: =SUM(B10,B11:B12,B13) -> 3315 | J14: Total Less in Fund | K14: =K11-K12+K13 -> 4590
A15: Fund Collection (3/15/25) | B15: ='FUND 2025'!G36 -> 580 | J15: FUND (2024) | K15: 21210
A16: TOTAL | B16: =SUM(B14:B15) -> 3895 | J16: Total | K16: =K15-K14 -> 16620
A17: Fund Collection (3/31/25) | B17: ='FUND 2025'!H36 -> 570 | J17: LESS: Sign Language (FOOD) | K17: 414
A18: TOTAL | B18: =B16+B17 -> 4465 | J18: Tree Planting Activity
A19: Fund Collection (4/15/25) | B19: ='FUND 2025'!I36 -> 520 | J19: LESS: Bamboo Stick | K19: 50
A20: Fund Collection (4/30/25) | B20: ='FUND 2025'!J36 -> 500 | J20: Mangrove & Transpo | K20: 300 | L20: =K17+K19+K20 -> 764
A21: TOTAL | B21: =SUM(B18:B20) -> 5485 | J21: Total | L21: =K16-L20 -> 15856
A22: Fund Collection (5/1/25) | B22: ='FUND 2025'!K36 -> 460 | J22: Fund Collection (Jan-July) | L22: =SUM(B4,B5,B9,B13,B15,B17,B19,B20,B22,B23:B26) -> 6650
A23: Fund Collection (5/31/25) | B23: ='FUND 2025'!L36 -> 420 | J23: Total | L23: =L21+L22 -> 22506
A24: Fund Collection (6/15/25) | B24: ='FUND 2025'!M36 -> 360 | G24: SARIAYA | H24: =25*2 -> 50 | J24: LESS: Ocular (MARYL, ALJO) | K24: 500
A25: Fund Collection (6/30/25) | B25: ='FUND 2025'!N36 -> 300 | G25: GUIS-GUIS | H25: =45*2 -> 90 | J25: GAS (BILER) | K25: 250 | L25: =K24+K25 -> 750
A26: Fund Collection (7/15/25) | B26: ='FUND 2025'!O36 -> 260 | G26: DEL PRADO | H26: =25*2 -> 50 | J26: Total | L26: =L23-L25 -> 21756
G27: PARAISO | H27: 60 | J27: LESS:
A28: TOTAL | B28: =SUM(B21:B27) -> 7285 | G28: JEEP | H28: =12*2+11*2 -> 46 | J28: ADDITIONAL FOR RESORT | K28: =1000 -> 1000
G29: TOTAL | H29: =SUM(H24:H28) -> 296 | J29: Utensils | K29: =48+50+50+51.7+110.25 -> 309.95
G30: TOTAL EXPENSE | H30: =H29*2 -> 592 | J30: Liqour | K30: =275+158.55+131 -> 564.55 | N30: Total R. Fund (Maryl) | O30: 17873
J31: Foods | K31: =132+61.75+65 -> 258.75
J32: Materials | K32: =58+43+59+14+35+75 -> 284
J33: Chips and Prizes | K33: =517.6+62.75 -> 580.35
F34: Beg. Bal | G34: 5446 | J34: Resort | K34: 6000
F35: Less: | J35: Service Fee | K35: 30
F36: Tarp | G36: 1000 | J36: AR. Dator | K36: 300
F37: Jeep | G37: 2000 | J37: AR. DR. Malot | K37: 35
F38: Backdrop | G38: 598 | J38: Paper Plate | K38: 110.25
G39: 110 | J39: Jeep | K39: 3200 | L39: =SUM(K28:K39) -> 12672.85
G40: 130 | J40: TOTAL FUND | L40: =L26-L39 -> 9083.15
G41: =95+140 -> 235 | H41: =SUM(G38:G41) -> 1073 | J41: ADD. CONTRIBUTION | L41: =150*29+50 -> 4400
F42: Token | G42: 41 | J42: Ma'am Alyssa | L42: =1600*2 -> 3200
G43: 51 | J43: TOTAL REMAINING FUND | L43: =L40+L41+L42 -> 16683.15
...

Sheet TEAM-B 2025 COSTING
A1: COSTING | H1: Costing for Team-Building | Q1: *2
E2: FINANCE | F2: 4000 | H2: 21 hrs | O2: Daytour | P2: 9 am -5 pm
A3: Foods | C3: =85*34 -> 2890 | E3: FUND | F3: ='2025 '!L26 -> 21756 | H3: Foods | J3: =C3 -> 2890 | O3: Foods | Q3: =J3 -> 2890
A4: Villa | C4: 13500 | F4: =F2+F3 -> 25756 | H4: Token | J4: =300*2 -> 600 | K4: =J3+J4 -> 3490 | M4: Drewn | O4: Token | Q4: =500*2 -> 1000
A5: Token | C5: =300*2 -> 600 | E5: BUDGETED | F5: 10000 | H5: Transportation | J5: =E12 -> 2950 | O5: Wrap | Q5: =55*2 -> 110 | R5: =Q3+Q5+Q4 -> 4000 | T5: Drewn
A6: TOTAL | C6: =SUM(C3:C5) -> 16990 | F6: =F4-F5 -> 15756 | H6: Villa | J6: =B16 -> 5750 | O6: Transportation | Q6: =J5 -> 2950
H7: Delivery Fee | J7: 200 | K7: =J5+J6+J7 -> 8900 | M7: FUND | O7: Villa | Q7: =P14 -> 2900
A8: Contribution | H8: Other Expense | K8: 300 | O8: Delivery Fee | Q8: 200 | R8: =Q6+Q7+Q8 -> 6050 | T8: FUND | V8: PASOBRA | W8: =15000-R10 -> 4650
H9: TOTAL COST | K9: =SUM(K4:K8) -> 12690 | O9: Other Expense | R9: 300
A10: Entrance | C10: =300*31 -> 9300 | O10: TOTAL COST | R10: =SUM(R5:R9) -> 10350
A11: Transportation | C11: =4500 -> 4500 | E11: =50*31 -> 1550 | F11: WOES | H11: Contribution
A12: TOTAL | C12: =SUM(C10:C11) -> 13800 | E12: =C11-E11 -> 2950 | F12: FUND | H12: Entrance | J12: =B15/31 -> 250 | K12: =B15 -> 7750 | O12: Villa | P12: 6000 | S12: Contribution | X12: =W15-100+'2025 '!L39-1000 -> 16072.85
H13: Transportation | J13: =60 -> 60 | K13: =E11 -> 1550 | O13: Entrance | P13: =100*31 -> 3100 | S13: Entrance | U13: =P13/31 -> 100 | V13: =U13*31 -> 3100
A14: Villa | B14: 13500 | H14: TOTAL COST | J14: =J12+J13 -> 310 | K14: =K12+K13 -> 9300 | P14: =P12-P13 -> 2900 | Q14: (less from Fund) | S14: Transportation | U14: 50 | V14: =K13 -> 1550
A15: Entrance | B15: =250*31 -> 7750 | J15: per head | S15: TOTAL COST | U15: =U13+U14 -> 150 | V15: =V13+V14 -> 4650 | W15: =150*30 -> 4500 | Y15: 2000
B16: =B14-B15 -> 5750 | C16: (less from Fund) | N16: Villa Leo Del | U16: per head | Y16: =V14 -> 1550
K17: PASOBRA | L17: =15000-K9 -> 2310 | N17: Brgy. Pahinga Sur, Candelaria Quezon | X17: R. BAL. | Y17: =5000-SUM(Y15:Y16) -> 1450 | Z17: =Y17+1500 -> 2950
N18: 2
A20: Foods | C20: =85*34 -> 2890
A21: Token | C21: =300*2 -> 600 | E21: Contribution
A22: Transportation | C22: =J5 -> 2950 | E22: Entrance | G22: 110 | H22: =G22*31 -> 3410
A23: Cottage | C23: 6000 | E23: Transportation | G23: =60 -> 60 | H23: =E11 -> 1550 | J23: Villa Del Prado
A24: Pub and Speakers | C24: =110*3 -> 330 | E24: TOTAL COST | G24: =G22+G23 -> 170 | H24: =H22+H23 -> 4960 | J24: Sariaya
A25: Videoke | C25: 1500
A26: Delivery Fee | C26: 200 | G26: PASOBRA | H26: =15000-C28 -> 230
A27: Other Expense | C27: 300
A28: TOTAL COST | C28: =SUM(C20:C27) -> 14770 | N28: 1
A31: FINANCE | B31: 4000
A32: FUND | B32: =F3 -> 21756
B33: =B31+B32 -> 25756
A36: Foods | C36: =85*34 -> 2890 | E36: Contribution
A37: Token | C37: =300*2 -> 600 | E37: Entrance | G37: 150 | H37: =G37*31 -> 4650
A38: Transportation | C38: =E12 -> 2950 | E38: Transportation | G38: =60 -> 60 | H38: =E11 -> 1550
A39: Cottage | C39: 5000 | E39: TOTAL COST | G39: =G37+G38 -> 210 | H39: =H37+H38 -> 6200
A40: Pub and Speakers | C40: =150*3 -> 450
A41: Delivery Fee | C41: 200 | G41: PASOBRA | H41: =15000-C44 -> 610 | J41: WILLIEMAC, SARIAYA
A42: Videoke | C42: 2000
A43: Other Expense | C43: 300 | N43: 1
A44: TOTAL COST | C44: =SUM(C36:C43) -> 14390
A46: FINANCE | B46: 4000
...

Sheet FUND 2026
A1: Names: | C1: 11505 | D1: 42217 | E1: 11536 | F1: 42248 | G1: 11202 | H1: 42278 | I1: 11597 | J1: 5784 | K1: 11628 | L1: 5814 | M1: 11658 | N1: 42019 | O1: 46053 | P1: 46068 | Q1: Feb 31 | R1: 46096 | S1: 46112 | T1: 46127 | U1: 46142 | V1: 46157 | W1: 46173 | X1: 46188
A2: Ancaja, Louise | C2: 20 | D2: 20 | E2: 20 | F2: 20 | G2: 20 | H2: 20 | I2: 20 | J2: 20 | K2: 20 | L2: 20
A3: Azores, Leslie | C3: 20 | D3: 20 | E3: 20 | F3: 20 | G3: 20 | H3: 20 | I3: 20 | J3: 20 | K3: 20
A4: Balanial, Pamela | C4: 20 | D4: 20 | E4: 20 | F4: 20 | G4: 20 | H4: 20 | I4: 20 | J4: 20 | K4: 20 | L4: 20 | M4: 20 | N4: 20 | O4: 20 | P4: 20 | Q4: 20
A5: Barco, Isabel | C5: 20 | D5: 20 | E5: 20 | F5: 20 | G5: 20 | H5: 20 | I5: 20 | J5: 20 | K5: 20
A6: Batad, Micha | C6: 20 | D6: 20 | E6: 20 | F6: 20 | G6: 20 | H6: 20 | I6: 20 | J6: 20 | K6: 20 | L6: 20 | M6: 20 | N6: 20 | O6: 20 | P6: 20 | Q6: 20 | R6: 20 | S6: 20
A7: Biler, Kehn | C7: 20 | D7: 20 | E7: 20 | F7: 20 | G7: 20 | H7: 20 | I7: 20 | J7: 20 | K7: 20 | L7: 20 | M7: 20
A8: Capistrano, Robiel | C8: 20 | D8: 20 | E8: 20 | F8: 20 | G8: 20 | H8: 20 | I8: 20 | J8: 20 | K8: 20 | L8: 20 | M8: 20 | N8: 20 | O8: 20 | P8: 20 | Q8: 20 | R8: 20 | S8: 20
A9: Dator,Jeffre | C9: 20 | D9: 20 | E9: 20 | F9: 20 | G9: 20 | H9: 20 | I9: 20 | J9: 20 | K9: 20 | L9: 20 | M9: 20 | N9: 20 | O9: 20 | P9: 20 | Q9: 20 | R9: 20 | S9: 20 | T9: 20 | U9: 20 | V9: 20
A10: De dios, Rea | C10: 20 | D10: 20 | E10: 20 | F10: 20 | G10: 20 | H10: 20 | I10: 20 | J10: 20 | K10: 20 | L10: 20 | M10: 20 | N10: 20
A11: Domanais, Karl | C11: 20 | D11: 20 | E11: 20 | F11: 20 | G11: 20 | H11: 20 | I11: 20
A12: Frias, Maryl | C12: 20 | D12: 20 | E12: 20 | F12: 20 | G12: 20 | H12: 20 | I12: 20 | J12: 20 | K12: 20 | L12: 20 | M12: 20 | N12: 20 | O12: 20 | P12: 20 | Q12: 20 | R12: 20
A13: Gaddi, Rex Jr. | C13: 20 | D13: 20 | E13: 20
A14: Garcia, Gracy | C14: NEW | D14: 20 | E14: 20 | F14: 20 | G14: 20 | H14: 20 | I14: 20 | J14: 20 | K14: 20 | L14: 20
A15: Gianan, Jean Nicole | C15: 20 | D15: 20 | E15: 20 | F15: 20 | G15: 20 | H15: 20 | I15: 20 | J15: 20 | K15: 20 | L15: 20 | M15: 20 | N15: 20 | O15: 20
A16: Guzman, Xyril | C16: 20 | D16: 20
A17: Lalisan, Quert | C17: 20 | D17: 20 | E17: 20 | F17: 20 | G17: 20 | H17: 20 | I17: 20 | J17: 20 | K17: 20 | L17: 20 | M17: 20 | N17: 20 | O17: 20 | P17: 20 | Q17: 20
A18: Labitigan, Reynalyn | C18: 20 | D18: 20 | E18: 20 | F18: 20 | G18: 20 | H18: 20 | I18: 20
A19: Laguna, Heleina | C19: 20 | D19: 20 | E19: 20 | F19: 20 | G19: 20 | H19: 20 | I19: 20 | J19: 20 | K19: 20 | L19: 20 | M19: 20 | N19: 20 | O19: 20 | P19: 20
A20: Macaraig, Jay Cee | C20: 20 | D20: 20 | E20: 20 | F20: 20 | G20: 20 | H20: 20 | I20: 20 | J20: 20 | K20: 20 | L20: 20 | M20: 20 | N20: 20 | O20: 20
A21: Malonzo, Nizza | C21: 20 | D21: 20 | E21: 20 | F21: 20 | G21: 20 | H21: 20 | I21: 20 | J21: 20 | K21: 20 | L21: 20 | M21: 20 | N21: 20 | O21: 20 | P21: 20
A22: Nieva, Ericka | C22: 20 | D22: 20 | E22: 20 | F22: 20 | G22: 20 | H22: 20 | I22: 20 | J22: 20 | K22: 20 | L22: 20 | M22: 20 | N22: 20 | O22: 20 | P22: 20 | Q22: 20
A23: Orte, James Miro | C23: NEW | D23: NEW | E23: 20 | F23: 20 | G23: 20 | H23: 20 | I23: 20
A24: Orozco, Maya | C24: 20 | D24: 20 | E24: 20 | F24: 20
A25: Quindoza, Aljo | C25: 20 | D25: 20 | E25: 20 | F25: 20 | G25: 20 | H25: 20 | I25: 20
A26: Rivera, Kate | C26: 20 | D26: 20 | E26: 20 | F26: 20 | G26: 20 | H26: 20 | I26: 20 | J26: 20 | K26: 20 | L26: 20 | M26: 20 | N26: 20 | O26: 20 | P26: 20
A27: Samante, Gian | C27: 20 | D27: 20 | E27: 20
A28: Sesgundo, Kim | C28: 20 | D28: 20 | E28: 20 | F28: 20 | G28: 20 | H28: 20 | I28: 20 | J28: 20 | K28: 20 | L28: 20 | M28: 20 | N28: 20 | O28: 20 | P28: 20 | Q28: 20 | R28: 20 | S28: 20 | T28: 20
A29: Tomenio, Alyssa | C29: 20 | D29: 20 | E29: 20 | F29: 20 | G29: 20 | H29: 20 | I29: 20 | J29: 20 | K29: 20 | L29: 20
A30: Valencia, Alexia | C30: 20 | D30: 20 | E30: 20 | F30: 20 | G30: 20 | H30: 20 | I30: 20 | J30: 20 | K30: 20 | L30: 20 | M30: 20 | N30: 20
A31: Vinas, Jiro | C31: 20 | D31: 20
A32: Claveria, Nace | C32: NEW | D32: NEW | E32: 20 | F32: 20 | G32: 20 | H32: 20 | I32: 20 | J32: 20 | K32: 20 | L32: 20 | M32: 20 | N32: 20 | O32: 20
A33: Baral, Khamlah | C33: 20 | D33: 20 | E33: 20 | F33: 20 | G33: 20 | H33: 20 | I33: 20 | J33: 20 | K33: 20 | L33: 20
A34: San Miguel, JV | C34: NEW | D34: 20 | E34: 20 | F34: 20 | G34: 20
A35: Carabido, Paul | C35: NEW | D35: NEW | E35: NEW | F35: 20 | G35: 20 | H35: 20 | I35: 20 | J35: 20 | K35: 20
A36: Cordovilla, Kate | C36: NEW | D36: NEW | E36: NEW | F36: 20 | G36: 20 | H36: 20
A37: Casipit, Lester | C37: NEW | J37: 20 | K37: 20 | L37: 20 | M37: 20 | N37: 20 | O37: 20 | P37: 20 | Q37: 20 | R37: 20 | S37: 20
A38: Merle, John Gabriel | C38: NEW | D38: NEW | E38: NEW | F38: NEW | G38: NEW | H38: NEW | I38: 20 | J38: 20 | K38: 20 | L38: 20 | M38: 20 | N38: 10
A39: Catalan, Daniel | C39: NEW | D39: NEW | E39: NEW | F39: 20 | G39: 20 | H39: 20 | I39: 20 | J39: 20 | K39: 20 | L39: 20 | M39: 20 | N39: 10
A40: Menemedez | B40: Andrei | C40: NEW | N40: NEW
...

Sheet 2026
A1: Total Fund | C1: 13141.5
A2: Less: Snacks for Sign Langauge | B2: 630
A3: Total Remaining Fund | C3: =C1-B2 -> 12511.5
A4: FUND COLLECTED (4/13/26) | B4: 1020
A5: Total Fund | C5: =C3+B4 -> 13531.5
A6: Less: LYDO Transpo | C6: 100
A7: Transportation | C7: 22
A8: Total Fund | C8: =C5-SUM(C7+C6) -> 13409.5
A12: Isabel R. Barco
A13: Treasurer, Alliance of Student Assistants
A16: Maryl France P. Frias
A17: President, Alliance of Student Assistants
A20: Dr. Mary Rose Q. Cabreros
A21: Adviser, Alliance of Student Assistants
